Workbook
Name Employmenttype: List!$A$1
Name Employment: List!$A$1:$A$3
Name jobtitle: List!$E:$E
Name gender: List!$D:$D
Name department: List!$C:$C
Name location: List!$B:$B

Sheet Original data data
A1: employee_id | B1: full_name | C1: gender | D1: department | E1: job_title | F1: employment_type | G1: location | H1: hire_date | I1: monthly_salary_bdt | J1: manager_id
A2: E0001 | B2: Lamia Talukder | C2: Female | D2: Sales | E2: Sales Associate | F2: Full-time | G2: Khulna | H2: 42776 | I2: 97605
A3: E0002 | B3: Ayesha Hasan | C3: Male | D3: Customer Success | E3: Support Specialist | F3: Intern | G3: Khulna | H3: 45178 | I3: 57499 | J3: E0890
A4: E0003 | B4: Sajid Rasheed | C4: Male | D4: Finance | E4: Finance Manager | F4: Full-time | G4: Remote | H4: 43874 | I4: 136659 | J4: E0990
A5: E0004 | B5: Shawon Rana | C5: Male | D5: HR | E5: HR Business Partner | F5: Full-time | G5: Sylhet | H5: 44600 | I5: 115085 | J5: E0982
A6: E0005 | B6: Zahid Morshed | C6: Female | D6: Engineering | E6: DevOps Engineer | F6: Full-time | G6: Dhaka | H6: 45011 | I6: 164000 | J6: E0741
A7: E0006 | B7: Rashed Uddin | C7: Female | D7: Engineering | E7: QA Engineer | F7: Full-time | G7: Dhaka | H7: 43839 | I7: 113810 | J7: E0775
A8: E0007 | B8: Karim Islam | C8: Female | D8: Engineering | E8: QA Engineer | F8: Contract | G8: Sylhet | H8: 42618 | I8: 148804 | J8: E0102
A9: E0008 | B9: Imran Ferdous | C9: Male | D9: Operations | E9: Operations Manager | F9: Full-time | G9: Khulna | H9: 44000 | I9: 163417 | J9: E0646
A10: E0009 | B10: Ayesha Biswas | C10: Male | D10: HR | E10: HR Associate | F10: Full-time | G10: Dhaka | H10: 43500 | I10: 59023 | J10: E0314
A11: E0010 | B11: Mitu Haider | C11: Male | D11: Finance | E11: Financial Analyst | F11: Full-time | G11: Chattogram | H11: 43147 | I11: 184800 | J11: E0380
A12: E0011 | B12: Lamia Ferdous | C12: Male | D12: Engineering | E12: Software Engineer | F12: Intern | G12: Remote | H12: 42870 | I12: 76400 | J12: E0648
A13: E0012 | B13: Sumaiya Parvin | C13: Male | D13: Customer Success | E13: Customer Success Manager | F13: Full-time | G13: Dhaka | H13: 45843 | I13: 91466 | J13: E0816
A14: E0013 | B14: Priya Mahmud | C14: Male | D14: Operations | E14: Operations Manager | F14: Contract | G14: Khulna | H14: 45745 | I14: 144623 | J14: E0396
... A36: E0035 | B36: Fahim Biswas | C36: Male | D36: Customer Success | E36: Support Associate | F36: Full-time | G36: Dhaka | H36: 44771 | I36: 116624 | J36: E0865
A37: E0036 | B37: Zahid Banu | C37: Female | D37: Operations | E37: Supply Chain Analyst | F37: Full-time | G37: Chattogram | H37: 43254 | I37: 77427
A38: E0037 | B38: Shawon Anjum | C38: Female | D38: Product | E38: Associate Product Manager | F38: Contract | G38: Dhaka | H38: 45700 | I38: 317015 | J38: E0380
A39: E0038 | B39: Mahin Miah | C39: Female | D39: Engineering | E39: QA Engineer | F39: Full-time | G39: Rajshahi | H39: 43324 | I39: 206071 | J39: E0701
A40: E0039 | B40: Sadia Biswas | C40: Female | D40: Finance | E40: Accounts Executive | F40: Contract | G40: Rajshahi | H40: 43715 | I40: 132584
A41: E0040 | B41: Shafiq Sadiq | C41: Female | D41: Sales | E41: Account Executive | F41: Full-time | G41: Rajshahi | H41: 45541 | I41: 74566 | J41: E0849
A42: E0041 | B42: Noman Khan | C42: Female | D42: Engineering | E42: Senior Software Engineer | F42: Full-time | G42: Khulna | H42: 42974 | I42: 164307 | J42: E0251
A43: E0042 | B43: Esha Amin | C43: Male | D43: Marketing | E43: SEO Specialist | F43: Full-time | G43: Khulna | H43: 45600 | I43: 143885 | J43: E0141
A44: E0043 | B44: Ovi Islam | C44: Male | D44: Engineering | E44: Software Engineer | F44: Full-time | G44: Remote | H44: 44811 | I44: 151772 | J44: E0736
A45: E0044 | B45: Fahim Jahan | C45: Male | D45: Customer Success | E45: Support Specialist | F45: Full-time | G45: Rajshahi | H45: 42381 | I45: 72635 | J45: E0186
A46: E0045 | B46: Rahim Akter | C46: Male | D46: Product | E46: Senior Product Manager | F46: Full-time | G46: Chattogram | H46: 43505 | I46: 228086 | J46: E0025
A47: E0046 | B47: Mitu Sharmin | C47: Male | D47: HR | E47: HR Business Partner | F47: Full-time | G47: Rajshahi | H47: 45886 | I47: 117000 | J47: E0456
A48: E0047 | B48: Noman Amin | C48: Male | D48: Product | E48: Product Analyst | F48: Full-time | G48: Rajshahi | H48: 42962 | I48: 104908 | J48: E0927
A49: E0048 | B49: Tania Ahmed | C49: Male | D49: Marketing | E49: Marketing Associate | F49: Full-time | G49: Khulna | H49: 42902 | I49: 134577 | J49: E0592
A50: E0049 | B50: Tasnim Shah | C50: Female | D50: Marketing | E50: Marketing Manager | F50: Full-time | G50: Chattogram | H50: 44582 | I50: 211918 | J50: E0783
A51: E0050 | B51: Rahim Rasheed | C51: Male | D51: Engineering | E51: Junior Software Engineer | F51: Full-time | G51: Dhaka | H51: 43396 | I51: 173897 | J51: E0383
A52: E0051 | B52: Noman Sultana | C52: Male | D52: Customer Success | E52: Customer Success Manager | F52: Contract | G52: Remote | H52: 45640 | I52: 121481 | J52: E0849
... A54: E0053 | B54: Shawon Akter | C54: Male | D54: Customer Success | E54: Customer Success Manager | F54: Full-time | G54: Sylhet | H54: 42820 | I54: 173570 | J54: E0701
A55: E0054 | B55: Tamanna Rahman | C55: Female | D55: Operations | E55: Operations Manager | F55: Full-time | G55: Dhaka | H55: 45077 | I55: 147590
A56: E0055 | B56: Tania Amin | C56: Female | D56: HR | E56: HR Manager | F56: Full-time | G56: Sylhet | H56: 42475 | I56: 138544 | J56: E0425
A57: E0056 | B57: Sadia Rasheed | C57: Female | D57: Customer Success | E57: Support Associate | F57: Full-time | G57: Rajshahi | H57: 42909 | I57: 89940 | J57: E0728
A58: E0057 | B58: Shawon Miah | C58: Male | D58: Engineering | E58: QA Engineer | F58: Full-time | G58: Rajshahi | H58: 42430 | I58: 209299 | J58: E0580
A59: E0058 | B59: Ayesha Parvin | C59: Female | D59: Engineering | E59: Software Engineer | F59: Full-time | G59: Remote | H59: 43837 | I59: 96715
A60: E0059 | B60: Sadia Miah | C60: Male | D60: Engineering | E60: Senior Software Engineer | F60: Full-time | G60: Remote | H60: 45605 | I60: 165688 | J60: E0184
A61: E0060 | B61: Nafiz Morshed | C61: Male | D61: Sales | E61: Senior Account Executive | F61: Full-time | G61: Remote | H61: 45599 | I61: 95553 | J61: E0839
A62: E0061 | B62: Fahim Biswas | C62: Non-binary | D62: Sales | E62: Sales Manager | F62: Full-time | G62: Dhaka | H62: 43344 | I62: 225796 | J62: E0453
...

Sheet abc_inc_employees_master
A1: employee_id | B1: full_name | C1: gender | D1: department | E1: job_title | F1: employment_type | G1: location | H1: hire_date | I1: monthly_salary_bdt | J1: manager_id | K1: Temporary column | L1: Median | M1: Tenure | N1: Tenure groups
A2: E0001 | B2: Lamia Talukder | C2: Female | D2: Sales | E2: Sales Associate | F2: Full-time | G2: Khulna | H2: 42776 | I2: 97605 | K2: =A2&B2&C2&D2&E2&F2&G2&H2&I2&J2&[1]Sheet1!$G$5 -> E0001Lamia TalukderFemaleSalesSales AssociateFull-timeKhulna4277697605Sylhet | L2: =MEDIAN(I2:I1001) -> 134130 | M2: =DATEDIF(H2,TODAY(),"Y") -> 9 | N2: =IF(M2<=2,"New",IF(M2<=5,"Mid level",IF(M2<=10,"Experienced","Long term"))) -> Experienced
A3: E0002 | B3: Ayesha Hasan | C3: Male | D3: Customer Success | E3: Support Specialist | F3: Intern | G3: Khulna | H3: 45178 | I3: 57499 | J3: E0890 | K3: =A3&B3&C3&D3&E3&F3&G3&H3&I3&J3&[1]Sheet1!$G$5 -> E0002Ayesha HasanMaleCustomer SuccessSupport SpecialistInternKhulna4517857499E0890Sylhet | L3: =MEDIAN(I3:I1002) -> 134271 | M3: =DATEDIF(H3,TODAY(),"Y") -> 2 | N3: =IF(M3<=2,"New",IF(M3<=5,"Mid level",IF(M3<=10,"Experienced","Long term"))) -> New
A4: E0003 | B4: Sajid Rasheed | C4: Male | D4: Finance | E4: Finance Manager | F4: Full-time | G4: Remote | H4: 43874 | I4: 136659 | J4: E0990 | K4: =A4&B4&C4&D4&E4&F4&G4&H4&I4&J4&[1]Sheet1!$G$5 -> E0003Sajid RasheedMaleFinanceFinance ManagerFull-timeRemote43874136659E0990Sylhet | L4: =MEDIAN(I4:I1003) -> 134276 | M4: =DATEDIF(H4,TODAY(),"Y") -> 6 | N4: =IF(M4<=2,"New",IF(M4<=5,"Mid level",IF(M4<=10,"Experienced","Long term"))) -> Experienced
A5: E0004 | B5: Shawon Rana | C5: Male | D5: HR | E5: HR Business Partner | F5: Full-time | G5: Sylhet | H5: 44600 | I5: 115085 | J5: E0982 | K5: =A5&B5&C5&D5&E5&F5&G5&H5&I5&J5&[1]Sheet1!$G$5 -> E0004Shawon RanaMaleHRHR Business PartnerFull-timeSylhet44600115085E0982Sylhet | L5: =MEDIAN(I5:I1004) -> 134271 | M5: =DATEDIF(H5,TODAY(),"Y") -> 4 | N5: =IF(M5<=2,"New",IF(M5<=5,"Mid level",IF(M5<=10,"Experienced","Long term"))) -> Mid level
A6: E0005 | B6: Zahid Morshed | C6: Female | D6: Engineering | E6: DevOps Engineer | F6: Full-time | G6: Dhaka | H6: 45011 | I6: 164000 | J6: E0741 | K6: =A6&B6&C6&D6&E6&F6&G6&H6&I6&J6&[1]Sheet1!$G$5 -> E0005Zahid MorshedFemaleEngineeringDevOps EngineerFull-timeDhaka45011164000E0741Sylhet | L6: =MEDIAN(I6:I1005) -> 134276 | M6: =DATEDIF(H6,TODAY(),"Y") -> 2 | N6: =IF(M6<=2,"New",IF(M6<=5,"Mid level",IF(M6<=10,"Experienced","Long term"))) -> New
A7: E0006 | B7: Rashed Uddin | C7: Female | D7: Engineering | E7: QA Engineer | F7: Full-time | G7: Dhaka | H7: 43839 | I7: 113810 | J7: E0775 | K7: =A7&B7&C7&D7&E7&F7&G7&H7&I7&J7&[1]Sheet1!$G$5 -> E0006Rashed UddinFemaleEngineeringQA EngineerFull-timeDhaka43839113810E0775Sylhet | L7: =MEDIAN(I7:I1006) -> 134271 | M7: =DATEDIF(H7,TODAY(),"Y") -> 6 | N7: =IF(M7<=2,"New",IF(M7<=5,"Mid level",IF(M7<=10,"Experienced","Long term"))) -> Experienced
A8: E0007 | B8: Karim Islam | C8: Female | D8: Engineering | E8: QA Engineer | F8: Contract | G8: Sylhet | H8: 42618 | I8: 148804 | J8: E0102 | K8: =A8&B8&C8&D8&E8&F8&G8&H8&I8&J8&[1]Sheet1!$G$5 -> E0007Karim IslamFemaleEngineeringQA EngineerContractSylhet42618148804E0102Sylhet | L8: =MEDIAN(I8:I1007) -> 134276 | M8: =DATEDIF(H8,TODAY(),"Y") -> 9 | N8: =IF(M8<=2,"New",IF(M8<=5,"Mid level",IF(M8<=10,"Experienced","Long term"))) -> Experienced
A9: E0008 | B9: Imran Ferdous | C9: Male | D9: Operations | E9: Operations Manager | F9: Full-time | G9: Khulna | H9: 44000 | I9: 163417 | J9: E0646 | K9: =A9&B9&C9&D9&E9&F9&G9&H9&I9&J9&[1]Sheet1!$G$5 -> E0008Imran FerdousMaleOperationsOperations ManagerFull-timeKhulna44000163417E0646Sylhet | L9: =MEDIAN(I9:I1008) -> 134271 | M9: =DATEDIF(H9,TODAY(),"Y") -> 5 | N9: =IF(M9<=2,"New",IF(M9<=5,"Mid level",IF(M9<=10,"Experienced","Long term"))) -> Mid level
A10: E0009 | B10: Ayesha Biswas | C10: Male | D10: HR | E10: HR Associate | F10: Full-time | G10: Dhaka | H10: 43500 | I10: 59023 | J10: E0314 | K10: =A10&B10&C10&D10&E10&F10&G10&H10&I10&J10&[1]Sheet1!$G$5 -> E0009Ayesha BiswasMaleHRHR AssociateFull-timeDhaka4350059023E0314Sylhet | L10: =MEDIAN(I10:I1009) -> 134130 | M10: =DATEDIF(H10,TODAY(),"Y") -> 7 | N10: =IF(M10<=2,"New",IF(M10<=5,"Mid level",IF(M10<=10,"Experienced","Long term"))) -> Experienced
A11: E0010 | B11: Mitu Haider | C11: Male | D11: Finance | E11: Financial Analyst | F11: Full-time | G11: Chattogram | H11: 43147 | I11: 184800 | J11: E0380 | K11: =A11&B11&C11&D11&E11&F11&G11&H11&I11&J11&[1]Sheet1!$G$5 -> E0010Mitu HaiderMaleFinanceFinancial AnalystFull-timeChattogram43147184800E0380Sylhet | L11: =MEDIAN(I11:I1010) -> 134271 | M11: =DATEDIF(H11,TODAY(),"Y") -> 8 | N11: =IF(M11<=2,"New",IF(M11<=5,"Mid level",IF(M11<=10,"Experienced","Long term"))) -> Experienced
A12: E0011 | B12: Lamia Ferdous | C12: Male | D12: Engineering | E12: Software Engineer | F12: Intern | G12: Remote | H12: 42870 | I12: 76400 | J12: E0648 | K12: =A12&B12&C12&D12&E12&F12&G12&H12&I12&J12&[1]Sheet1!$G$5 -> E0011Lamia FerdousMaleEngineeringSoftware EngineerInternRemote4287076400E0648Sylhet | L12: =MEDIAN(I12:I1011) -> 134130 | M12: =DATEDIF(H12,TODAY(),"Y") -> 8 | N12: =IF(M12<=2,"New",IF(M12<=5,"Mid level",IF(M12<=10,"Experienced","Long term"))) -> Experienced
A13: E0012 | B13: Sumaiya Parvin | C13: Male | D13: Customer Success | E13: Customer Success Manager | F13: Full-time | G13: Dhaka | H13: 45843 | I13: 91466 | J13: E0816 | K13: =A13&B13&C13&D13&E13&F13&G13&H13&I13&J13&[1]Sheet1!$G$5 -> E0012Sumaiya ParvinMaleCustomer SuccessCustomer Success ManagerFull-timeDhaka4584391466E0816Sylhet | L13: =MEDIAN(I13:I1012) -> 134271 | M13: =DATEDIF(H13,TODAY(),"Y") -> 0 | N13: =IF(M13<=2,"New",IF(M13<=5,"Mid level",IF(M13<=10,"Experienced","Long term"))) -> New
A14: E0013 | B14: Priya Mahmud | C14: Male | D14: Operations | E14: Operations Manager | F14: Contract | G14: Khulna | H14: 45745 | I14: 144623 | J14: E0396 | K14: =A14&B14&C14&D14&E14&F14&G14&H14&I14&J14&[1]Sheet1!$G$5 -> E0013Priya MahmudMaleOperationsOperations ManagerContractKhulna45745144623E0396Sylhet | L14: =MEDIAN(I14:I1013) -> 134276 | M14: =DATEDIF(H14,TODAY(),"Y") -> 0 | N14: =IF(M14<=2,"New",IF(M14<=5,"Mid level",IF(M14<=10,"Experienced","Long term"))) -> New
... A36: E0035 | B36: Fahim Biswas | C36: Male | D36: Customer Success | E36: Support Associate | F36: Full-time | G36: Dhaka | H36: 44771 | I36: 116624 | J36: E0865 | K36: =A36&B36&C36&D36&E36&F36&G36&H36&I36&J36&[1]Sheet1!$G$5 -> E0035Fahim BiswasMaleCustomer SuccessSupport AssociateFull-timeDhaka44771116624E0865Sylhet | L36: =MEDIAN(I36:I1035) -> 134130 | M36: =DATEDIF(H36,TODAY(),"Y") -> 3 | N36: =IF(M36<=2,"New",IF(M36<=5,"Mid level",IF(M36<=10,"Experienced","Long term"))) -> Mid level
A37: E0036 | B37: Zahid Banu | C37: Female | D37: Operations | E37: Supply Chain Analyst | F37: Full-time | G37: Chattogram | H37: 43254 | I37: 77427 | K37: =A37&B37&C37&D37&E37&F37&G37&H37&I37&J37&[1]Sheet1!$G$5 -> E0036Zahid BanuFemaleOperationsSupply Chain AnalystFull-timeChattogram4325477427Sylhet | L37: =MEDIAN(I37:I1036) -> 134271 | M37: =DATEDIF(H37,TODAY(),"Y") -> 7 | N37: =IF(M37<=2,"New",IF(M37<=5,"Mid level",IF(M37<=10,"Experienced","Long term"))) -> Experienced
A38: E0037 | B38: Shawon Anjum | C38: Female | D38: Product | E38: Associate Product Manager | F38: Contract | G38: Dhaka | H38: 45700 | I38: 317015 | J38: E0380 | K38: =A38&B38&C38&D38&E38&F38&G38&H38&I38&J38&[1]Sheet1!$G$5 -> E0037Shawon AnjumFemaleProductAssociate Product ManagerContractDhaka45700317015E0380Sylhet | L38: =MEDIAN(I38:I1037) -> 134276 | M38: =DATEDIF(H38,TODAY(),"Y") -> 1 | N38: =IF(M38<=2,"New",IF(M38<=5,"Mid level",IF(M38<=10,"Experienced","Long term"))) -> New
A39: E0038 | B39: Mahin Miah | C39: Female | D39: Engineering | E39: QA Engineer | F39: Full-time | G39: Rajshahi | H39: 43324 | I39: 206071 | J39: E0701 | K39: =A39&B39&C39&D39&E39&F39&G39&H39&I39&J39&[1]Sheet1!$G$5 -> E0038Mahin MiahFemaleEngineeringQA EngineerFull-timeRajshahi43324206071E0701Sylhet | L39: =MEDIAN(I39:I1038) -> 134271 | M39: =DATEDIF(H39,TODAY(),"Y") -> 7 | N39: =IF(M39<=2,"New",IF(M39<=5,"Mid level",IF(M39<=10,"Experienced","Long term"))) -> Experienced
A40: E0039 | B40: Sadia Biswas | C40: Female | D40: Finance | E40: Accounts Executive | F40: Contract | G40: Rajshahi | H40: 43715 | I40: 132584 | K40: =A40&B40&C40&D40&E40&F40&G40&H40&I40&J40&[1]Sheet1!$G$5 -> E0039Sadia BiswasFemaleFinanceAccounts ExecutiveContractRajshahi43715132584Sylhet | L40: =MEDIAN(I40:I1039) -> 134130 | M40: =DATEDIF(H40,TODAY(),"Y") -> 6 | N40: =IF(M40<=2,"New",IF(M40<=5,"Mid level",IF(M40<=10,"Experienced","Long term"))) -> Experienced
A41: E0040 | B41: Shafiq Sadiq | C41: Female | D41: Sales | E41: Account Executive | F41: Full-time | G41: Rajshahi | H41: 45541 | I41: 74566 | J41: E0849 | K41: =A41&B41&C41&D41&E41&F41&G41&H41&I41&J41&[1]Sheet1!$G$5 -> E0040Shafiq SadiqFemaleSalesAccount ExecutiveFull-timeRajshahi4554174566E0849Sylhet | L41: =MEDIAN(I41:I1040) -> 134271 | M41: =DATEDIF(H41,TODAY(),"Y") -> 1 | N41: =IF(M41<=2,"New",IF(M41<=5,"Mid level",IF(M41<=10,"Experienced","Long term"))) -> New
A42: E0041 | B42: Noman Khan | C42: Female | D42: Engineering | E42: Senior Software Engineer | F42: Full-time | G42: Khulna | H42: 42974 | I42: 164307 | J42: E0251 | K42: =A42&B42&C42&D42&E42&F42&G42&H42&I42&J42&[1]Sheet1!$G$5 -> E0041Noman KhanFemaleEngineeringSenior Software EngineerFull-timeKhulna42974164307E0251Sylhet | L42: =MEDIAN(I42:I1041) -> 134276 | M42: =DATEDIF(H42,TODAY(),"Y") -> 8 | N42: =IF(M42<=2,"New",IF(M42<=5,"Mid level",IF(M42<=10,"Experienced","Long term"))) -> Experienced
A43: E0042 | B43: Esha Amin | C43: Male | D43: Marketing | E43: SEO Specialist | F43: Full-time | G43: Khulna | H43: 45600 | I43: 143885 | J43: E0141 | K43: =A43&B43&C43&D43&E43&F43&G43&H43&I43&J43&[1]Sheet1!$G$5 -> E0042Esha AminMaleMarketingSEO SpecialistFull-timeKhulna45600143885E0141Sylhet | L43: =MEDIAN(I43:I1042) -> 134271 | M43: =DATEDIF(H43,TODAY(),"Y") -> 1 | N43: =IF(M43<=2,"New",IF(M43<=5,"Mid level",IF(M43<=10,"Experienced","Long term"))) -> New
A44: E0043 | B44: Ovi Islam | C44: Male | D44: Engineering | E44: Software Engineer | F44: Full-time | G44: Remote | H44: 44811 | I44: 151772 | J44: E0736 | K44: =A44&B44&C44&D44&E44&F44&G44&H44&I44&J44&[1]Sheet1!$G$5 -> E0043Ovi IslamMaleEngineeringSoftware EngineerFull-timeRemote44811151772E0736Sylhet | L44: =MEDIAN(I44:I1043) -> 134130 | M44: =DATEDIF(H44,TODAY(),"Y") -> 3 | N44: =IF(M44<=2,"New",IF(M44<=5,"Mid level",IF(M44<=10,"Experienced","Long term"))) -> Mid level
A45: E0044 | B45: Fahim Jahan | C45: Male | D45: Customer Success | E45: Support Specialist | F45: Full-time | G45: Rajshahi | H45: 42381 | I45: 72635 | J45: E0186 | K45: =A45&B45&C45&D45&E45&F45&G45&H45&I45&J45&[1]Sheet1!$G$5 -> E0044Fahim JahanMaleCustomer SuccessSupport SpecialistFull-timeRajshahi4238172635E0186Sylhet | L45: =MEDIAN(I45:I1044) -> 133989 | M45: =DATEDIF(H45,TODAY(),"Y") -> 10 | N45: =IF(M45<=2,"New",IF(M45<=5,"Mid level",IF(M45<=10,"Experienced","Long term"))) -> Experienced
A46: E0045 | B46: Rahim Akter | C46: Male | D46: Product | E46: Senior Product Manager | F46: Full-time | G46: Chattogram | H46: 43505 | I46: 228086 | J46: E0025 | K46: =A46&B46&C46&D46&E46&F46&G46&H46&I46&J46&[1]Sheet1!$G$5 -> E0045Rahim AkterMaleProductSenior Product ManagerFull-timeChattogram43505228086E0025Sylhet | L46: =MEDIAN(I46:I1045) -> 134130 | M46: =DATEDIF(H46,TODAY(),"Y") -> 7 | N46: =IF(M46<=2,"New",IF(M46<=5,"Mid level",IF(M46<=10,"Experienced","Long term"))) -> Experienced
A47: E0046 | B47: Mitu Sharmin | C47: Male | D47: HR | E47: HR Business Partner | F47: Full-time | G47: Rajshahi | H47: 45886 | I47: 117000 | J47: E0456 | K47: =A47&B47&C47&D47&E47&F47&G47&H47&I47&J47&[1]Sheet1!$G$5 -> E0046Mitu SharminMaleHRHR Business PartnerFull-timeRajshahi45886117000E0456Sylhet | L47: =MEDIAN(I47:I1046) -> 133989 | M47: =DATEDIF(H47,TODAY(),"Y") -> 0 | N47: =IF(M47<=2,"New",IF(M47<=5,"Mid level",IF(M47<=10,"Experienced","Long term"))) -> New
A48: E0047 | B48: Noman Amin | C48: Male | D48: Product | E48: Product Analyst | F48: Full-time | G48: Rajshahi | H48: 42962 | I48: 104908 | J48: E0927 | K48: =A48&B48&C48&D48&E48&F48&G48&H48&I48&J48&[1]Sheet1!$G$5 -> E0047Noman AminMaleProductProduct AnalystFull-timeRajshahi42962104908E0927Sylhet | L48: =MEDIAN(I48:I1047) -> 134130 | M48: =DATEDIF(H48,TODAY(),"Y") -> 8 | N48: =IF(M48<=2,"New",IF(M48<=5,"Mid level",IF(M48<=10,"Experienced","Long term"))) -> Experienced
A49: E0048 | B49: Tania Ahmed | C49: Male | D49: Marketing | E49: Marketing Associate | F49: Full-time | G49: Khulna | H49: 42902 | I49: 134577 | J49: E0592 | K49: =A49&B49&C49&D49&E49&F49&G49&H49&I49&J49&[1]Sheet1!$G$5 -> E0048Tania AhmedMaleMarketingMarketing AssociateFull-timeKhulna42902134577E0592Sylhet | L49: =MEDIAN(I49:I1048) -> 134271 | M49: =DATEDIF(H49,TODAY(),"Y") -> 8 | N49: =IF(M49<=2,"New",IF(M49<=5,"Mid level",IF(M49<=10,"Experienced","Long term"))) -> Experienced
A50: E0049 | B50: Tasnim Shah | C50: Female | D50: Marketing | E50: Marketing Manager | F50: Full-time | G50: Chattogram | H50: 44582 | I50: 211918 | J50: E0783 | K50: =A50&B50&C50&D50&E50&F50&G50&H50&I50&J50&[1]Sheet1!$G$5 -> E0049Tasnim ShahFemaleMarketingMarketing ManagerFull-timeChattogram44582211918E0783Sylhet | L50: =MEDIAN(I50:I1049) -> 134130 | M50: =DATEDIF(H50,TODAY(),"Y") -> 4 | N50: =IF(M50<=2,"New",IF(M50<=5,"Mid level",IF(M50<=10,"Experienced","Long term"))) -> Mid level
A51: E0050 | B51: Rahim Rasheed | C51: Male | D51: Engineering | E51: Junior Software Engineer | F51: Full-time | G51: Dhaka | H51: 43396 | I51: 173897 | J51: E0383 | K51: =A51&B51&C51&D51&E51&F51&G51&H51&I51&J51&[1]Sheet1!$G$5 -> E0050Rahim RasheedMaleEngineeringJunior Software EngineerFull-timeDhaka43396173897E0383Sylhet | L51: =MEDIAN(I51:I1050) -> 133989 | M51: =DATEDIF(H51,TODAY(),"Y") -> 7 | N51: =IF(M51<=2,"New",IF(M51<=5,"Mid level",IF(M51<=10,"Experienced","Long term"))) -> Experienced
A52: E0051 | B52: Noman Sultana | C52: Male | D52: Customer Success | E52: Customer Success Manager | F52: Contract | G52: Remote | H52: 45640 | I52: 121481 | J52: E0849 | K52: =A52&B52&C52&D52&E52&F52&G52&H52&I52&J52&[1]Sheet1!$G$5 -> E0051Noman SultanaMaleCustomer SuccessCustomer Success ManagerContractRemote45640121481E0849Sylhet | L52: =MEDIAN(I52:I1051) -> 133901 | M52: =DATEDIF(H52,TODAY(),"Y") -> 1 | N52: =IF(M52<=2,"New",IF(M52<=5,"Mid level",IF(M52<=10,"Experienced","Long term"))) -> New
... A54: E0053 | B54: Shawon Akter | C54: Male | D54: Customer Success | E54: Customer Success Manager | F54: Full-time | G54: Sylhet | H54: 42820 | I54: 173570 | J54: E0701 | K54: =A54&B54&C54&D54&E54&F54&G54&H54&I54&J54&[1]Sheet1!$G$5 -> E0053Shawon AkterMaleCustomer SuccessCustomer Success ManagerFull-timeSylhet42820173570E0701Sylhet | L54: =MEDIAN(I54:I1053) -> 133901 | M54: =DATEDIF(H54,TODAY(),"Y") -> 8 | N54: =IF(M54<=2,"New",IF(M54<=5,"Mid level",IF(M54<=10,"Experienced","Long term"))) -> Experienced
A55: E0054 | B55: Tamanna Rahman | C55: Female | D55: Operations | E55: Operations Manager | F55: Full-time | G55: Dhaka | H55: 45077 | I55: 147590 | K55: =A55&B55&C55&D55&E55&F55&G55&H55&I55&J55&[1]Sheet1!$G$5 -> E0054Tamanna RahmanFemaleOperationsOperations ManagerFull-timeDhaka45077147590Sylhet | L55: =MEDIAN(I55:I1054) -> 133813 | M55: =DATEDIF(H55,TODAY(),"Y") -> 2 | N55: =IF(M55<=2,"New",IF(M55<=5,"Mid level",IF(M55<=10,"Experienced","Long term"))) -> New
A56: E0055 | B56: Tania Amin | C56: Female | D56: HR | E56: HR Manager | F56: Full-time | G56: Sylhet | H56: 42475 | I56: 138544 | J56: E0425 | K56: =A56&B56&C56&D56&E56&F56&G56&H56&I56&J56&[1]Sheet1!$G$5 -> E0055Tania AminFemaleHRHR ManagerFull-timeSylhet42475138544E0425Sylhet | L56: =MEDIAN(I56:I1055) -> 133779.5 | M56: =DATEDIF(H56,TODAY(),"Y") -> 9 | N56: =IF(M56<=2,"New",IF(M56<=5,"Mid level",IF(M56<=10,"Experienced","Long term"))) -> Experienced
A57: E0056 | B57: Sadia Rasheed | C57: Female | D57: Customer Success | E57: Support Associate | F57: Full-time | G57: Rajshahi | H57: 42909 | I57: 89940 | J57: E0728 | K57: =A57&B57&C57&D57&E57&F57&G57&H57&I57&J57&[1]Sheet1!$G$5 -> E0056Sadia RasheedFemaleCustomer SuccessSupport AssociateFull-timeRajshahi4290989940E0728Sylhet | L57: =MEDIAN(I57:I1056) -> 133746 | M57: =DATEDIF(H57,TODAY(),"Y") -> 8 | N57: =IF(M57<=2,"New",IF(M57<=5,"Mid level",IF(M57<=10,"Experienced","Long term"))) -> Experienced
A58: E0057 | B58: Shawon Miah | C58: Male | D58: Engineering | E58: QA Engineer | F58: Full-time | G58: Rajshahi | H58: 42430 | I58: 209299 | J58: E0580 | K58: =A58&B58&C58&D58&E58&F58&G58&H58&I58&J58&[1]Sheet1!$G$5 -> E0057Shawon MiahMaleEngineeringQA EngineerFull-timeRajshahi42430209299E0580Sylhet | L58: =MEDIAN(I58:I1057) -> 133779.5 | M58: =DATEDIF(H58,TODAY(),"Y") -> 10 | N58: =IF(M58<=2,"New",IF(M58<=5,"Mid level",IF(M58<=10,"Experienced","Long term"))) -> Experienced
A59: E0058 | B59: Ayesha Parvin | C59: Female | D59: Engineering | E59: Software Engineer | F59: Full-time | G59: Remote | H59: 43837 | I59: 96715 | K59: =A59&B59&C59&D59&E59&F59&G59&H59&I59&J59&[1]Sheet1!$G$5 -> E0058Ayesha ParvinFemaleEngineeringSoftware EngineerFull-timeRemote4383796715Sylhet | L59: =MEDIAN(I59:I1058) -> 133746 | M59: =DATEDIF(H59,TODAY(),"Y") -> 6 | N59: =IF(M59<=2,"New",IF(M59<=5,"Mid level",IF(M59<=10,"Experienced","Long term"))) -> Experienced
A60: E0059 | B60: Sadia Miah | C60: Male | D60: Engineering | E60: Senior Software Engineer | F60: Full-time | G60: Remote | H60: 45605 | I60: 165688 | J60: E0184 | K60: =A60&B60&C60&D60&E60&F60&G60&H60&I60&J60&[1]Sheet1!$G$5 -> E0059Sadia MiahMaleEngineeringSenior Software EngineerFull-timeRemote45605165688E0184Sylhet | L60: =MEDIAN(I60:I1059) -> 133779.5 | M60: =DATEDIF(H60,TODAY(),"Y") -> 1 | N60: =IF(M60<=2,"New",IF(M60<=5,"Mid level",IF(M60<=10,"Experienced","Long term"))) -> New
A61: E0060 | B61: Nafiz Morshed | C61: Male | D61: Sales | E61: Senior Account Executive | F61: Full-time | G61: Remote | H61: 45599 | I61: 95553 | J61: E0839 | K61: =A61&B61&C61&D61&E61&F61&G61&H61&I61&J61&[1]Sheet1!$G$5 -> E0060Nafiz MorshedMaleSalesSenior Account ExecutiveFull-timeRemote4559995553E0839Sylhet | L61: =MEDIAN(I61:I1060) -> 133746 | M61: =DATEDIF(H61,TODAY(),"Y") -> 1 | N61: =IF(M61<=2,"New",IF(M61<=5,"Mid level",IF(M61<=10,"Experienced","Long term"))) -> New
A62: E0061 | B62: Fahim Biswas | C62: Non-binary | D62: Sales | E62: Sales Manager | F62: Full-time | G62: Dhaka | H62: 43344 | I62: 225796 | J62: E0453 | K62: =A62&B62&C62&D62&E62&F62&G62&H62&I62&J62&[1]Sheet1!$G$5 -> E0061Fahim BiswasNon-binarySalesSales ManagerFull-timeDhaka43344225796E0453Sylhet | L62: =MEDIAN(I62:I1061) -> 133779.5 | M62: =DATEDIF(H62,TODAY(),"Y") -> 7 | N62: =IF(M62<=2,"New",IF(M62<=5,"Mid level",IF(M62<=10,"Experienced","Long term"))) -> Experienced
...

Sheet Requirements
A1: Data Preparation and Validation
A3: · Verify that employee identifiers are unique.
A5: · Ensure salary values are valid and greater than zero.
A7: · Identify and document missing reporting structure or location information.
A9: · Confirm that date fields are correctly formatted and logically consistent.
A11: · Standardize department and job title naming conventions.
A12: Analytical Questions
A14: 1. What is the distribution of employees across departments?
A16: 2. Which departments employ the largest number of staff members?
A18: 3. How is the workforce distributed across employment types?
A20: 4. Which locations host the largest number of employees?
A22: 5. What is the average compensation level within each department?
... A47: · Column chart presenting average tenure across departments.

Sheet List
A1: {=_xlfn.UNIQUE(abc_inc_employees_master!F2:F1001)} -> Full-time | B1: {=_xlfn.UNIQUE(abc_inc_employees_master!G2:G1001)} -> Khulna | C1: {=_xlfn.UNIQUE(abc_inc_employees_master!D2:D1001)} -> Sales | D1: {=_xlfn.UNIQUE(abc_inc_employees_master!C2:C1001)} -> Female | E1: {=_xlfn.UNIQUE(abc_inc_employees_master!E2:E1001)} -> Sales Associate
A2: Intern | B2: Remote | C2: Customer Success | D2: Male | E2: Support Specialist
A3: Contract | B3: Sylhet | C3: Finance | D3: Non-binary | E3: Finance Manager
B4: Dhaka | C4: HR | D4: Prefer not to say | E4: HR Business Partner
B5: Chattogram | C5: Engineering | E5: DevOps Engineer
B6: Rajshahi | C6: Operations | E6: QA Engineer
C7: Product | E7: Operations Manager
C8: Marketing | E8: HR Associate
E9: Financial Analyst
E10: Software Engineer
E11: Customer Success Manager
E12: Junior Software Engineer
E13: Engineering Manager
E14: Product Analyst
E15: Growth Marketer
E16: Sales Manager
E17: Senior Product Manager
E18: Supply Chain Analyst
E19: SEO Specialist
E20: Recruiter
... E33: Content Specialist

Sheet distribution 
A1: 1. What is the distribution of employees across departments?
A3: department | B3: Count of job_title
A4: Customer Success | B4: 100
A5: Engineering | B5: 238
A6: Finance | B6: 86
A7: HR | B7: 90
A8: Marketing | B8: 119
A9: Operations | B9: 126
A10: Product | B10: 94
A11: Sales | B11: 147
A12: (blank)
A13: Grand Total | B13: 1000

Sheet Sheet5
A2: 3. How is the workforce distributed across employment types?
A3: employment_type | B3: Count of employment_type
A4: Contract | B4: 120
A5: Full-time | B5: 832
A6: Intern | B6: 48
A7: Grand Total | B7: 1000

Sheet Sheet6
A3: location | B3: Count of location
A4: Chattogram | B4: 175
A5: Dhaka | B5: 179
A6: Khulna | B6: 173
A7: Rajshahi | B7: 155
A8: Remote | B8: 174
A9: Sylhet | B9: 144
A10: Grand Total | B10: 1000

Sheet Sheet8
C1: 4. Which locations host the largest number of employees?
A3: department | B3: Average of monthly_salary_bdt | C3: 5. What is the average compensation level within each department?
A4: Customer Success | B4: 99688.61
A5: Engineering | B5: 160669.97
A6: Finance | B6: 162531.94
A7: HR | B7: 102747.16
A8: Marketing | B8: 126445.07
A9: Operations | B9: 116932.31
A10: Product | B10: 210305.56
A11: Sales | B11: 142930.27
A12: (blank)
A13: Grand Total | B13: 141993.21

Sheet Sheet11
A3: job_title | B3: Count of manager_id
A4: Associate Product Manager | B4: 18
A5: Customer Success Manager | B5: 32
A6: Engineering Manager | B6: 19
A7: Finance Manager | B7: 11
A8: HR Manager | B8: 20
A9: Marketing Manager | B9: 16
A10: Operations Manager | B10: 33
A11: Product Manager | B11: 20
A12: Sales Manager | B12: 25
A13: Senior Product Manager | B13: 25
A14: Grand Total | B14: 219

Sheet Sheet13
A3: department | B3: job_title | C3: Average of Tenure | D3: Count of department
A4: Customer Success | C4: 4.63 | D4: 100
B5: Customer Success Manager | C5: 4.8235294 | D5: 34
B6: Support Associate | C6: 4.1515152 | D6: 33
B7: Support Specialist | C7: 4.9090909 | D7: 33
A8: Engineering | C8: 5.1008403 | D8: 238
B9: DevOps Engineer | C9: 4.5483871 | D9: 31
B10: Engineering Manager | C10: 3.5909091 | D10: 22
B11: Junior Software Engineer | C11: 5.3035714 | D11: 56
B12: QA Engineer | C12: 5.225 | D12: 40
B13: Senior Software Engineer | C13: 5.6052632 | D13: 38
B14: Software Engineer | C14: 5.3921569 | D14: 51
A15: Finance | C15: 4.7209302 | D15: 86
B16: Accounts Executive | C16: 4.173913 | D16: 23
B17: Finance Manager | C17: 5.3333333 | D17: 12
B18: Financial Analyst | C18: 4.9583333 | D18: 24
B19: Senior Financial Analyst | C19: 4.7037037 | D19: 27
A20: HR | C20: 4.4666667 | D20: 90
B21: HR Associate | C21: 4.4444444 | D21: 27
B22: HR Business Partner | C22: 4.4375 | D22: 16
B23: HR Manager | C23: 4.6818182 | D23: 22
B24: Recruiter | C24: 4.32 | D24: 25
A25: Marketing | C25: 5.1260504 | D25: 119
B26: Content Specialist | C26: 4.5151515 | D26: 33
B27: Growth Marketer | C27: 5.1363636 | D27: 22
B28: Marketing Associate | C28: 5.1666667 | D28: 30
B29: Marketing Manager | C29: 5.0555556 | D29: 18
B30: SEO Specialist | C30: 6.375 | D30: 16
A31: Operations | C31: 4.5952381 | D31: 126
B32: Operations Associate | C32: 4.3095238 | D32: 42
B33: Operations Manager | C33: 5.2432432 | D33: 37
B34: Supply Chain Analyst | C34: 4.3404255 | D34: 47
A35: Product | C35: 4.6170213 | D35: 94
B36: Associate Product Manager | C36: 5.1818182 | D36: 22
B37: Product Analyst | C37: 4.7307692 | D37: 26
B38: Product Manager | C38: 4.1428571 | D38: 21
B39: Senior Product Manager | C39: 4.4 | D39: 25
A40: Sales | C40: 4.9931973 | D40: 147
B41: Account Executive | C41: 5.4594595 | D41: 37
B42: Sales Associate | C42: 4.4883721 | D42: 43
...

Sheet Sheet14
A3: department | B3: Sum of Tenure
A4: Customer Success | B4: 463
A5: Engineering | B5: 1214
A6: Finance | B6: 406
A7: HR | B7: 402
A8: Marketing | B8: 610
A9: Operations | B9: 579
A10: Product | B10: 434
A11: Sales | B11: 734
A12: Grand Total | B12: 4842

Sheet Sheet15
A3: department | B3: Tenure groups | C3: Count of Tenure groups
A4: Customer Success | C4: 100
B5: Experienced | C5: 39
B6: Mid level | C6: 34
B7: New | C7: 27
A8: Engineering | C8: 238
B9: Experienced | C9: 117
B10: Mid level | C10: 61
B11: New | C11: 60
A12: Finance | C12: 86
B13: Experienced | C13: 35
B14: Mid level | C14: 30
B15: New | C15: 21
A16: HR | C16: 90
B17: Experienced | C17: 33
B18: Mid level | C18: 28
B19: New | C19: 29
A20: Marketing | C20: 119
B21: Experienced | C21: 55
B22: Mid level | C22: 43
B23: New | C23: 21
A24: Operations | C24: 126
B25: Experienced | C25: 51
B26: Mid level | C26: 39
B27: New | C27: 36
A28: Product | C28: 94
B29: Experienced | C29: 36
B30: Mid level | C30: 31
B31: New | C31: 27
A32: Sales | C32: 147
B33: Experienced | C33: 67
B34: Mid level | C34: 43
B35: New | C35: 37
A36: Grand Total | C36: 1000
A38: In all departments, the majority of employees fall into the experienced category, followed by mid-level, and then new employees. This indicates that departments generally retain employees for longer periods, resulting in a workforce dominated by experienced members.”
A39: This distribution suggests that the organization may focus on retaining experienced staff to maintain knowledge continuity and ensure operational stability. Experienced employees likely provide mentorship to newer staff, which could explain the consistently higher numbers across departments
A40: In conclusion, the pattern between employee tenure and department is consistent
